<robot name="rbx1_urdf">
  <link name="world"/>
  <joint name="fixed" type="fixed">
    <parent link="world"/>
    <child link="base_link"/>
  </joint>
  <link name="base_link">
    <inertial>
      <origin xyz="0.034155 -0.20591 -0.049641" rpy="0 0 0" />
      <mass value="8.0643" />
      <inertia ixx="0.11291" ixy="0.00066071" ixz="-0.00030472"
       iyy="0.089946" iyz="0.011461" izz="0.19187" />
    </inertial>
    <visual>
      <origin xyz="0 0 0" rpy="0 0 0" />
      <geometry>
        <mesh filename="package://rbx1_urdf/meshes/base_link.STL" />
      </geometry>
      <material name="">
        <color rgba="0.75294 0.75294 0.75294 1" />
      </material>
    </visual>
    <collision>
      <origin xyz="0 0 0" rpy="0 0 0" />
      <geometry>
        <mesh filename="package://rbx1_urdf/meshes/base_link.STL" />
      </geometry>
    </collision>
  </link>
  <link name="link_1_shoulder">
    <inertial>
      <origin xyz="4.0186E-05 0.090634 0.00010221" rpy="0 0 0" />
      <mass value="4.2526" />
      <inertia ixx="0.0034071" ixy="8.9041E-06" ixz="1.179E-07"
       iyy="0.018642" iyz="-3.6544E-06" izz="0.021987" />
    </inertial>
    <visual>
      <origin xyz="0 0 0" rpy="0 0 0" />
      <geometry>
        <mesh filename="package://rbx1_urdf/meshes/link_1_shoulder.STL" />
      </geometry>
      <material name="">
        <color rgba="0.86 0.08 0.23 1" />
      </material>
    </visual>
    <collision>
      <origin xyz="0 0 0" rpy="0 0 0" />
      <geometry>
        <mesh filename="package://rbx1_urdf/meshes/collision/link_1_shoulder.STL" />
      </geometry>
    </collision>
  </link>
  <joint name="joint_1_base_shoulder" type="revolute">
    <origin xyz="0 -0.2425 0" rpy="1.5708 9.5417E-17 2.7766" />
    <parent link="base_link" />
    <child link="link_1_shoulder" />
    <axis xyz="0 1 0" />
    <limit lower="-1" upper="1" effort="5" velocity="1" />
  </joint>
  <link name="link_2_arm">
    <inertial>
      <origin xyz="2.2815E-05 0.0017616 -0.080002" rpy="0 0 0" />
      <mass value="1.9323" />
      <inertia ixx="0.012138" ixy="-3.5576E-06" ixz="-9.0632E-06"
       iyy="0.011445" iyz="0.00014273" izz="0.00070271" />
    </inertial>
    <visual>
      <origin xyz="0 0 0" rpy="0 0 0" />
      <geometry>
        <mesh filename="package://rbx1_urdf/meshes/link_2_arm.STL" />
      </geometry>
      <material name="">
        <color rgba="0.86 0.08 0.23 1" />
      </material>
    </visual>
    <collision>
      <origin xyz="0 0 0" rpy="0 0 0" />
      <geometry>
        <mesh filename="package://rbx1_urdf/meshes/collision/link_2_arm.STL" />
      </geometry>
    </collision>
  </link>
  <joint name="joint_2_shoulder_arm" type="revolute">
    <origin xyz="0 0.18264 0" rpy="-3.1416 0.95134 1.5708" />
    <parent link="link_1_shoulder" />
    <child link="link_2_arm" />
    <axis xyz="0 -1 0" />
    <limit lower="-1" upper="1" effort="5" velocity="1" />
  </joint>
  <link name="link_3_upper_forearm">
    <inertial>
      <origin xyz="0.05095 -0.00039084 -0.00045591" rpy="0 0 0" />
      <mass value="1.1381" />
      <inertia ixx="0.00023572" ixy="-3.8425E-06" ixz="4.1286E-06"
       iyy="0.00029123" iyz="-1.0387E-07" izz="0.00052457" />
    </inertial>
    <visual>
      <origin xyz="0 0 0" rpy="0 0 0" />
      <geometry>
        <mesh filename="package://rbx1_urdf/meshes/link_3_upper_forearm.STL" />
      </geometry>
      <material name="">
        <color rgba="0.86 0.08 0.23 1" />
      </material>
    </visual>
    <collision>
      <origin xyz="0 0 0" rpy="0 0 0" />
      <geometry>
        <mesh filename="package://rbx1_urdf/meshes/collision/link_3_upper_forearm.STL" />
      </geometry>
    </collision>
  </link>
  <joint name="joint_3_arm_upper_forearm" type="revolute">
    <origin xyz="0 0 -0.22112" rpy="-3.1416 0.98126 -3.1416" />
    <parent link="link_2_arm" />
    <child link="link_3_upper_forearm" />
    <axis xyz="0 -1 0" />
    <limit lower="-1" upper="1" effort="5" velocity="1" />
  </joint>
  <link name="link_4_forearm">
    <inertial>
      <origin xyz="-0.0027417 0.0025097 0.012864" rpy="0 0 0" />
      <mass value="0.62964" />
      <inertia ixx="0.0001717" ixy="1.3446E-06" ixz="8.5164E-06"
       iyy="0.00010506" iyz="5.1412E-05" izz="7.8944E-05" />
    </inertial>
    <visual>
      <origin xyz="0 0 0" rpy="0 0 0" />
      <geometry>
        <mesh filename="package://rbx1_urdf/meshes/link_4_forearm.STL" />
      </geometry>
      <material name="">
        <color rgba="0.86 0.08 0.23 1" />
      </material>
    </visual>
    <collision>
      <origin xyz="0 0 0" rpy="0 0 0" />
      <geometry>
        <mesh filename="package://rbx1_urdf/meshes/collision/link_4_forearm.STL" />
      </geometry>
    </collision>
  </link>
  <joint name="joint_4_upper_forearm_forearm" type="revolute">
    <origin xyz="0.16988 -0.00099213 0" rpy="3.1416 -1.2279 1.5708" />
    <parent link="link_3_upper_forearm" />
    <child link="link_4_forearm" />
    <axis xyz="0.010353 -0.99993 -0.0059382" />
    <limit lower="-1" upper="1" effort="5" velocity="1" />
  </joint>
  <link name="link_5_wrist">
    <inertial>
      <origin xyz="-0.011366 0.00012239 0.0078967" rpy="0 0 0" />
      <mass value="0.15" />
      <inertia ixx="6.2676E-05" ixy="4.2551E-06" ixz="4.0215E-05"
       iyy="9.7792E-05" iyz="8.5888E-07" izz="9.5807E-05" />
    </inertial>
    <visual>
      <origin xyz="0 0 0" rpy="0 0 0" />
      <geometry>
        <mesh filename="package://rbx1_urdf/meshes/link_5_wrist.STL" />
      </geometry>
      <material name="">
        <color rgba="0.86 0.08 0.23 1" />
      </material>
    </visual>
    <collision>
      <origin xyz="0 0 0" rpy="0 0 0" />
      <geometry>
        <mesh filename="package://rbx1_urdf/meshes/collision/link_5_wrist.STL" />
      </geometry>
    </collision>
  </link>
  <joint name="joint_5_forearm_wrist" type="revolute">
    <origin xyz="-0.0021346 0.053041 0.0016936" rpy="-1.5639 -0.091135 -0.00062919" />
    <parent link="link_4_forearm" />
    <child link="link_5_wrist" />
    <axis xyz="0 1 0" />
    <limit lower="-1" upper="1" effort="5" velocity="1" />
  </joint>
  <link name="link_6_hand">
    <inertial>
      <origin xyz="-0.011366 0.00012239 0.0078967" rpy="0 0 0" />
      <mass value="0.04"/>
      <inertia ixx="1.0" ixy="0.0" ixz="0.0"
        iyy="1.0" iyz="0.0" izz="1.0" />
    </inertial>
    <visual>
      <origin xyz="0 0 0" rpy="0 0 0" />
      <geometry>
        <mesh filename="package://rbx1_urdf/meshes/link_6_hand.STL" />
      </geometry>
      <material name="">
        <color rgba="0.86 0.08 0.23 1" />
      </material>
    </visual>
    <collision>
      <origin xyz="0 0 0" rpy="0 0 0" />
      <geometry>
        <mesh filename="package://rbx1_urdf/meshes/collision/link_6_hand.STL" />
      </geometry>
    </collision>
  </link>
  <joint name="joint_6_wrist_hand" type="revolute">
    <origin xyz="-0.034 0.0 0.024" rpy="0 0.645772 0" />
    <parent link="link_5_wrist" />
    <child link="link_6_hand" />
    <axis xyz="1 0 0" />
    <limit lower="-1" upper="1" effort="5" velocity="1" />
  </joint>
   <link name="gripper_servo_gear">
    <inertial>
      <origin xyz="0 0 0" rpy="0 0 0" />
      <mass value="0.0048997" />
      <inertia ixx="2.0097E-09" ixy="-3.0673E-09" ixz="-6.3297E-10" iyy="4.9761E-09" iyz="-3.9668E-10" izz="6.8221E-09" />
    </inertial>
    <visual>
      <origin xyz="0 0 0" rpy="0 0 0" />
      <geometry>
        <mesh filename="package://rbx1_urdf/meshes/gripper_servo_gear.STL" />
      </geometry>
      <material name="">
        <color rgba="0.9098 0.44314 0.031373 1" />
      </material>
    </visual>
    <collision>
      <origin xyz="0 0 0" rpy="0 0 0" />
      <geometry>
        <mesh filename="package://rbx1_urdf/meshes/collision/gripper_servo_gear.STL" />
      </geometry>
    </collision>
  </link>
 <joint name="gripper_servo_gear_joint" type="revolute">
    <origin xyz="-0.024077 0.014019 0.003057" rpy="1.5708 0.0 -1.5708" />
    <parent link="link_6_hand" />
    <child link="gripper_servo_gear" />
    <axis xyz="0 1 0" />
    <limit lower="0" upper="1.5707" effort="5" velocity="1" />
  </joint>
  
  <link name="tip_gripper_servo">
    <inertial>
      <origin xyz="0.028047 -0.000564 0.0049632" rpy="0 0 0" />
      <mass value="0.010676" />
      <inertia ixx="8.9609E-09" ixy="6.3808E-09" ixz="-2.6788E-08" iyy="1.7457E-07" iyz="7.7239E-10" izz="1.7361E-07" />
    </inertial>
    <visual>
      <origin xyz="0 0 0" rpy="0 0 0" />
      <geometry>
        <mesh filename="package://rbx1_urdf/meshes/tip_gripper_servo.STL" />
      </geometry>
      <material name="">
        <color rgba="0.6 1 0.27843 1" />
      </material>
    </visual>
    <collision>
      <origin xyz="0 0 0" rpy="0 0 0" />
      <geometry>
        <mesh filename="package://rbx1_urdf/meshes/collision/tip_gripper_servo.STL" />
      </geometry>
    </collision>
  </link>
  <joint name="tip_gripper_servo_joint" type="revolute">
    <origin xyz="-0.039906 -0.004 -0.0027473" rpy="-3.1416 -1.5569 -2.0392E-12" />
    <parent link="gripper_servo_gear" />
    <child link="tip_gripper_servo" />
    <axis xyz="0 1 0" />
    <limit lower="0" upper="1.3" effort="5" velocity="1" />
    <mimic joint="gripper_servo_gear_joint" multiplier="1" offset="0"/>
  </joint>
  <link name="gripper_idol_gear">
    <inertial>
      <origin xyz="0 0 0" rpy="0 0 0" />
      <mass value="0.0051273" />
      <inertia ixx="2.3661E-09" ixy="1.1076E-09" ixz="5.5775E-10" iyy="8.8855E-09" iyz="-6.98E-11" izz="1.1181E-08" />
    </inertial>
    <visual>
      <origin xyz="0 0 0" rpy="0 0 0" />
      <geometry>
        <mesh filename="package://rbx1_urdf/meshes/gripper_idol_gear.STL" />
      </geometry>
      <material name="">
        <color rgba="0.058824 0.64706 1 1" />
      </material>
    </visual>
    <collision>
      <origin xyz="0 0 0" rpy="0 0 0" />
      <geometry>
        <mesh filename="package://rbx1_urdf/meshes/collision/gripper_idol_gear.STL" />
      </geometry>
    </collision>
  </link>
  <joint name="gripper_idol_gear_joint" type="revolute">
    <origin xyz="-0.024233 -0.013715 -0.00052" rpy="1.5708 0.0 1.5708" />
    <parent link="link_6_hand" />
    <child link="gripper_idol_gear" />
    <axis xyz="0 1 0" />
    <limit lower="0" upper="-1.5707" effort="5" velocity="1" />
  </joint>
  <link name="tip_gripper_idol">
    <inertial>
      <origin xyz="0 0 0" rpy="0 0 0" />
      <mass value="0.010676" />
      <inertia ixx="1.6298E-07" ixy="-2.1098E-09" ixz="-4.8536E-08" iyy="1.7457E-07" iyz="-6.0724E-09" izz="1.9597E-08" />
    </inertial>
    <visual>
      <origin xyz="0 0 0" rpy="0 0 0" />
      <geometry>
        <mesh filename="package://rbx1_urdf/meshes/tip_gripper_idol.STL" />
      </geometry>
      <material name="">
        <color rgba="0.79216 0.81961 0.93333 1" />
      </material>
    </visual>
    <collision>
      <origin xyz="0 0 0" rpy="0 0 0" />
      <geometry>
        <mesh filename="package://rbx1_urdf/meshes/collision/tip_gripper_idol.STL" />
      </geometry>
    </collision>
  </link>
  <joint name="tip_gripper_idol_joint" type="revolute">
    <origin xyz="-0.040206 0 -0.001701" rpy="-3.1416 0.5236 -3.1416" />
    <parent link="gripper_idol_gear" />
    <child link="tip_gripper_idol" />
    <axis xyz="0 1 0" />
    <limit lower="-1" upper="1" effort="5" velocity="1" />
    <mimic joint="gripper_idol_gear_joint" multiplier="-1" offset="0"/>
  </joint>
  <link name="pivot_arm_gripper_servo">
    <inertial>
      <origin xyz="0 0 0" rpy="0 0 0" />
      <mass value="0.0018597" />
      <inertia ixx="2.3350521316943E-09" ixy="3.15938078443685E-09" ixz="-1.08844692176622E-09"
       iyy="7.82558758772591E-08" iyz="4.39516056818752E-11" izz="8.05606441237718E-08" />
    </inertial>
    <visual>
      <origin xyz="0 0 0" rpy="0 0 0" />
      <geometry>
        <mesh filename="package://rbx1_urdf/meshes/pivot_arm_gripper_servo.STL" />
      </geometry>
      <material name="">
        <color rgba="0.792156862745098 0.819607843137255 0.933333333333333 1" />
      </material>
    </visual>
    <collision>
      <origin xyz="0 0 0" rpy="0 0 0" />
      <geometry>
        <mesh filename="package://rbx1_urdf/meshes/collision/pivot_arm_gripper_servo.STL" />
      </geometry>
    </collision>
  </link>
  <joint name="pivot_arm_gripper_servo_joint" type="revolute">
    <origin xyz="-0.044253 0.007042 -0.000282" rpy="1.5708 0.0 -1.6308" />
    <parent link="link_6_hand" />
    <child link="pivot_arm_gripper_servo" />
    <axis xyz="0 1 0" />
    <limit lower="-1" upper="1" effort="5" velocity="1" />
    <mimic joint="gripper_servo_gear_joint" multiplier="1" offset="0"/> 
  </joint>
  <link name="pivot_arm_gripper_idol">
    <inertial>
      <origin xyz="0 0 0" rpy="0 0 0" />
      <mass value="0.0018597" />
      <inertia ixx="2.3203E-09" ixy="-3.1597E-09" ixz="1.7754E-10" 
       iyy="7.8256E-08" iyz="7.1682E-12" izz="8.0575E-08" />
    </inertial>
    <visual>
      <origin xyz="0 0 0" rpy="0 0 0" />
      <geometry>
        <mesh filename="package://rbx1_urdf/meshes/pivot_arm_gripper_idol.STL" />
      </geometry>
      <material name="">
        <color rgba="0.79216 0.81961 0.93333 1" />
      </material>
    </visual>
    <collision>
      <origin xyz="0 0 0" rpy="0 0 0" />
      <geometry>
        <mesh filename="package://rbx1_urdf/meshes/collision/pivot_arm_gripper_idol.STL" />
      </geometry>
    </collision>
  </link>
  <joint name="pivot_arm_gripper_idol_joint" type="revolute">
    <origin xyz="-0.044291 -0.007028 -0.000002" rpy="1.5708 0.0 -1.5708" />
    <parent link="link_6_hand" />
    <child link="pivot_arm_gripper_idol" />
    <axis xyz="0 1 0" />
    <limit lower="-1" upper="1" effort="5" velocity="1" />
    <mimic joint="gripper_idol_gear_joint" multiplier="1" offset="0"/> 
  </joint>
</robot>
